<?xml version="1.0" ?>
<sdf version="1.9">
    <model name='kestrel_drone'>
        <pose>0 0 0.25 0 0 0</pose>
        <link name='base_link'>
        <velocity_decay>
            <linear>0.0</linear>
            <angular>0.0</angular>
        </velocity_decay>
        <inertial>
            <pose>0.008 -0.0003 0.006 0 0 0</pose>
            <mass>1.6</mass>
            <inertia>
            <ixx>0.0055</ixx>
            <ixy>0</ixy>
            <ixz>0</ixz>
            <iyy>0.0067</iyy>
            <iyz>0</iyz>
            <izz>0.0099</izz>
            </inertia>
        </inertial>
        <collision name='base_link_collision'>
            <pose>0 0 0 0 0 0</pose>
            <geometry>
            <box>
                <size>0.358541 0.358541 0.212</size>
            </box>
            </geometry>
            <surface>
            <contact>
                <ode>
                <max_vel>100.0</max_vel>
                <min_depth>0.001</min_depth>
                </ode>
            </contact>
            <friction>
                <ode>
                <mu>100000.0</mu>
                <mu2>100000.0</mu2>
                </ode>
            </friction>
            </surface>
        </collision>
        <visual name='base_link_visual'>
            <pose>0 0 0 0 0 0</pose>
            <geometry>
                <mesh>
                    <scale>1 1 1</scale>
                    <uri>model://kestrel_drone/meshes/base_link.STL</uri>
                </mesh>
            </geometry>
            <material>
                <ambient>0.05 0.05 0.05</ambient>
                <diffuse>0.05 0.05 0.05</diffuse>
                <specular>1 1 1 1</specular>
                <pbr>
                    <metal>
                        <metalness>0.5</metalness>
                        <roughness>0.5</roughness>
                    </metal>
                </pbr>
            </material>
        </visual>
        </link>
        <joint name='CameraPt1-joint' type='revolute'>
        <pose relative_to='base_link'>0.1087 0 -0.051799999999999999 0 0 -0.016688999999999996</pose>
        <parent>base_link</parent>
        <child>CameraPt1</child>
        <axis>
            <xyz>0 0 1</xyz>
            <limit>
            <effort>1.4710000000000001</effort>
            <velocity>5.2359999999999998</velocity>
            <lower>0</lower>
            <upper>3.1415</upper>
            </limit>
            <dynamics>
                <spring_reference>0</spring_reference>
                <spring_stiffness>0</spring_stiffness>
            </dynamics>
        </axis>
        </joint>
        <link name='CameraPt1'>
        <pose relative_to='CameraPt1-joint'>0 0 0 0 0 0</pose>
        <inertial>
            <pose>-0.10077 -0.0019816999999999999 0.058075000000000002 0 0 0</pose>
            <mass>0.01</mass>
            <inertia>
            <ixx>0.0054891000000000002</ixx>
            <ixy>-1.2663000000000001e-05</ixy>
            <ixz>0.00018552999999999999</ixz>
            <iyy>0.0066689999999999996</iyy>
            <iyz>1.8978000000000001e-06</iyz>
            <izz>0.0098706999999999996</izz>
            </inertia>
        </inertial>
        <collision name='CameraPt1_collision'>
            <pose>0 0 0 0 0 0</pose>
            <geometry>
            <mesh>
                <scale>1 1 1</scale>
                <uri>model://kestrel_drone/meshes/CameraPt1.STL</uri>
            </mesh>
            </geometry>
        </collision>
        <visual name='CameraPt1_visual'>
            <pose>0 0 0 0 0 0</pose>
            <geometry>
            <mesh>
                <scale>1 1 1</scale>
                <uri>model://kestrel_drone/meshes/CameraPt1.STL</uri>
            </mesh>
            </geometry>
            <material>
                <diffuse>1 1 1 1</diffuse>
                <ambient>1 1 1 1</ambient>
                <pbr>
                    <metal>
                        <metalness>0.5</metalness>
                        <roughness>0.5</roughness>
                    </metal>
                </pbr>
            </material>
        </visual>
        </link>
        <joint name='CameraPt2-joint' type='revolute'>
        <pose relative_to='CameraPt1'>0.011849999999999999 0 0.0079000000000000008 0 0.0053803999999999996 0</pose>
        <parent>CameraPt1</parent>
        <child>CameraPt2</child>
        <axis>
            <xyz>0 -1 0</xyz>
            <limit>
            <effort>1.571</effort>
            <velocity>5.236</velocity>
            <lower>-1.5708</lower>
            <upper>0</upper>
            </limit>
            <dynamics>
            <spring_reference>0</spring_reference>
            <spring_stiffness>0</spring_stiffness>
            </dynamics>
        </axis>
        </joint>
        <link name='CameraPt2'>
        <pose relative_to='CameraPt2-joint'>0 0 0 0 0 0</pose>
        <inertial>
            <pose>-0.11289 -0.0019816999999999999 0.049568000000000001 0 0 0</pose>
            <mass>0.01</mass>
            <inertia>
            <ixx>0.0054872000000000002</ixx>
            <ixy>-1.2673e-05</ixy>
            <ixz>0.00016194000000000001</ixz>
            <iyy>0.0066689999999999996</iyy>
            <iyz>1.8296e-06</iyz>
            <izz>0.0098724999999999993</izz>
            </inertia>
        </inertial>
        <collision name='CameraPt2_collision'>
            <pose>0 0 0 0 0 0</pose>
            <geometry>
            <mesh>
                <scale>1 1 1</scale>
                <uri>model://kestrel_drone/meshes/CameraPt2.STL</uri>
            </mesh>
            </geometry>
        </collision>
        <visual name='CameraPt2_visual'>
            <pose>0 0 0 0 0 0</pose>
            <geometry>
            <mesh>
                <scale>1 1 1</scale>
                <uri>model://kestrel_drone/meshes/CameraPt2.STL</uri>
            </mesh>
            </geometry>
            <material>
                <diffuse>1 1 1 1</diffuse>
                <ambient>1 1 1 1</ambient>
                <pbr>
                    <metal>
                        <metalness>0.5</metalness>
                        <roughness>0.5</roughness>
                    </metal>
                </pbr>
            </material>
        </visual>
        <sensor name="camera" type="camera">
            <pose>0 0 0 0 0 0</pose>
            <camera>
            <horizontal_fov>2.0</horizontal_fov>
            <image>
                <width>640</width>
                <height>480</height>
            </image>
            <clip>
                <near>0.05</near>
                <far>15000</far>
            </clip>
            </camera>
            <always_on>1</always_on>
            <update_rate>10</update_rate>
            <visualize>1</visualize>
            <topic>/camera/rgb/image_raw</topic>

            <plugin filename="CameraZoomPlugin"
                name="CameraZoomPlugin">
            <max_zoom>125.0</max_zoom>
            <slew_rate>0.42514285714</slew_rate>
            </plugin>
            
            <plugin name="GstCameraPlugin"
                filename="GstCameraPlugin">
            <udp_host>127.0.0.1</udp_host>
            <udp_port>5600</udp_port>
            <use_basic_pipeline>true</use_basic_pipeline>
            <use_cuda>false</use_cuda>
            </plugin>

        </sensor>

        </link>
        <joint name='Prop1-joint' type='revolute'>
            <pose relative_to='base_link'>0.15846 -0.15891 0.055962 0 0 0</pose>
            <parent>base_link</parent>
            <child>Prop1</child>
            <axis>
                <xyz>0 0 1</xyz>
                <limit>
                    <lower>-Inf</lower>
                    <upper>Inf</upper>
                </limit>
                <dynamics>
                    <damping>0.005</damping>
                </dynamics>
            </axis>
            <physics>
                <ode>
                <implicit_spring_damper>1</implicit_spring_damper>
                </ode>
            </physics>
        </joint>
        <link name='Prop1'>
            <pose relative_to='Prop1-joint'>0 0 0 0 0 0</pose>
            <inertial>
                <pose>-0.0000001705 0.0094872 -0.000012556 0 0 0</pose>
                <mass>0.025</mass>
                <inertia>
                    <ixx>9.75e-06</ixx>
                    <ixy>0</ixy>
                    <ixz>0</ixz>
                    <iyy>0.000166704</iyy>
                    <iyz>0</iyz>
                    <izz>0.000167604</izz>
                </inertia>
            </inertial>
            <collision name='Prop1_collision'>
                <pose>0 0 0 0 0 0</pose>
                <geometry>
                    <cylinder>
                        <length>0.005</length>
                        <radius>0.1</radius>
                    </cylinder>
                </geometry>
                <surface>
                <contact>
                    <ode/>
                </contact>
                <friction>
                    <ode/>
                </friction>
                </surface>
            </collision>
            <visual name='Prop1_visual'>
                <pose>0 0 0 0 0 0</pose>
                <geometry>
                    <mesh>
                        <scale>1 1 1</scale>
                        <uri>model://kestrel_drone/meshes/Prop1.STL</uri>
                    </mesh>
                </geometry>
                <material>
                <diffuse>1 1 1 1</diffuse>
                <ambient>1 1 1 1</ambient>
                <pbr>
                    <metal>
                        <metalness>0.5</metalness>
                        <roughness>0.5</roughness>
                    </metal>
                </pbr>
                </material>
            </visual>
            <gravity>1</gravity>
            <velocity_decay/>
            <self_collide>0</self_collide>
        </link>
        <joint name='Prop2-joint' type='revolute'>
            <pose relative_to='base_link'>-0.15846 0.15891 0.055962 0 0 0</pose>
            <parent>base_link</parent>
            <child>Prop2</child>
            <axis>
                <xyz>0 0 1</xyz>
                <limit>
                    <lower>-Inf</lower>
                    <upper>Inf</upper>
                </limit>
                <dynamics>
                    <damping>0.005</damping>
                </dynamics>
            </axis>
            <physics>
                <ode>
                <implicit_spring_damper>1</implicit_spring_damper>
                </ode>
            </physics>
        </joint>
        <link name='Prop2'>
            <pose relative_to='Prop2-joint'>0 0 0 0 0 0</pose>
            <inertial>
                <pose>-0.0000001705 0.0094872 -0.000012556 0 0 0</pose>
                <mass>0.025</mass>
                <inertia>
                    <ixx>9.75e-06</ixx>
                    <ixy>0</ixy>
                    <ixz>0</ixz>
                    <iyy>0.000166704</iyy>
                    <iyz>0</iyz>
                    <izz>0.000167604</izz>
                </inertia>
            </inertial>
            <collision name='Prop2_collision'>
                <pose>0 0 0 0 0 0</pose>
                <geometry>
                    <cylinder>
                        <length>0.005</length>
                        <radius>0.1</radius>
                    </cylinder>
                </geometry>
                <surface>
                <contact>
                    <ode/>
                </contact>
                <friction>
                    <ode/>
                </friction>
                </surface>
            </collision>
            <visual name='Prop2_visual'>
                <pose>0 0 0 0 0 0</pose>
                <geometry>
                <mesh>
                    <scale>1 1 1</scale>
                    <uri>model://kestrel_drone/meshes/Prop2.STL</uri>
                </mesh>
                </geometry>
                <material>
                <diffuse>1 1 1 1</diffuse>
                <ambient>1 1 1 1</ambient>
                <pbr>
                    <metal>
                        <metalness>0.5</metalness>
                        <roughness>0.5</roughness>
                    </metal>
                </pbr>
                </material>
            </visual>
            <gravity>1</gravity>
            <velocity_decay/>
            <self_collide>0</self_collide>
        </link>
        <joint name='Prop3-joint' type='revolute'>
            <pose relative_to='base_link'>0.15891 0.15846 0.055962 0 0 0</pose>
            <parent>base_link</parent>
            <child>Prop3</child>
            <axis>
                <xyz>0 0 1</xyz>
                <limit>
                    <lower>-Inf</lower>
                    <upper>Inf</upper>
                </limit>
                <dynamics>
                    <damping>0.005</damping>
                </dynamics>
            </axis>
            <physics>
                <ode>
                <implicit_spring_damper>1</implicit_spring_damper>
                </ode>
            </physics>
        </joint>
        <link name='Prop3'>
            <pose relative_to='Prop3-joint'>0 0 0 0 0 0</pose>
            <inertial>
                <pose>-0.0000001705 0.0094872 -0.000012556 0 0 0</pose>
                <mass>0.018153</mass>
                <mass>0.025</mass>
                <inertia>
                    <ixx>9.75e-06</ixx>
                    <ixy>0</ixy>
                    <ixz>0</ixz>
                    <iyy>0.000166704</iyy>
                    <iyz>0</iyz>
                    <izz>0.000167604</izz>
                </inertia>
            </inertial>
            <collision name='Prop3_collision'>
                <pose>0 0 0 0 0 0</pose>
                <geometry>
                    <cylinder>
                        <length>0.005</length>
                        <radius>0.1</radius>
                    </cylinder>
                </geometry>
                <surface>
                <contact>
                    <ode/>
                </contact>
                <friction>
                    <ode/>
                </friction>
                </surface>
            </collision>
            <visual name='Prop3_visual'>
                <pose>0 0 0 0 0 0</pose>
                <geometry>
                    <mesh>
                        <scale>1 1 1</scale>
                        <uri>model://kestrel_drone/meshes/Prop3.STL</uri>
                    </mesh>
                </geometry>
                <material>
                <diffuse>1 1 1 1</diffuse>
                <ambient>1 1 1 1</ambient>
                <pbr>
                    <metal>
                        <metalness>0.5</metalness>
                        <roughness>0.5</roughness>
                    </metal>
                </pbr>
                </material>
            </visual>
            <gravity>1</gravity>
            <velocity_decay/>
            <self_collide>0</self_collide>
        </link>
        <joint name='Prop4-joint' type='revolute'>
            <pose relative_to='base_link'>-0.15891 -0.15846 0.055962 0 0 0</pose>
            <parent>base_link</parent>
            <child>Prop4</child>
            <axis>
                <xyz>0 0 1</xyz>
                <limit>
                    <lower>-Inf</lower>
                    <upper>Inf</upper>
                </limit>
                <dynamics>
                    <damping>0.005</damping>
                </dynamics>
            </axis>
            <physics>
                <ode>
                <implicit_spring_damper>1</implicit_spring_damper>
                </ode>
            </physics>
        </joint>
        <link name='Prop4'>
        <pose relative_to='Prop4-joint'>0 0 0 0 0 0</pose>
        <inertial>
            <pose>-0.0000001705 0.0094872 -0.000012556 0 0 0</pose>
            <mass>0.025</mass>
            <inertia>
                <ixx>9.75e-06</ixx>
                <ixy>0</ixy>
                <ixz>0</ixz>
                <iyy>0.000166704</iyy>
                <iyz>0</iyz>
                <izz>0.000167604</izz>
            </inertia>
        </inertial>
        <collision name='Prop4_collision'>
            <pose>0 0 0 0 0 0</pose>
            <geometry>
                <cylinder>
                    <length>0.005</length>
                    <radius>0.1</radius>
                </cylinder>
            </geometry>
            <surface>
            <contact>
                <ode/>
            </contact>
            <friction>
                <ode/>
            </friction>
            </surface>
        </collision>
        <visual name='Prop4_visual'>
            <pose>0 0 0 0 0 0</pose>
            <geometry>
                <mesh>
                    <scale>1 1 1</scale>
                    <uri>model://kestrel_drone/meshes/Prop4.STL</uri>
                </mesh>
            </geometry>
            <material>
            <diffuse>1 1 1 1</diffuse>
            <ambient>1 1 1 1</ambient>
            <pbr>
                <metal>
                    <metalness>0.5</metalness>
                    <roughness>0.5</roughness>
                </metal>
            </pbr>
            </material>
        </visual>
        <gravity>1</gravity>
        <velocity_decay/>
        <self_collide>0</self_collide>
        </link>

        <link name='imu_link'>
            <inertial>
                <pose>0 0 0 0 0 0</pose>
                <mass>0.15</mass>
                <inertia>
                <ixx>0.00001</ixx>
                <ixy>0</ixy>
                <ixz>0</ixz>
                <iyy>0.00002</iyy>
                <iyz>0</iyz>
                <izz>0.00002</izz>
                </inertia>
            </inertial>
            <sensor name="imu_sensor" type="imu">
                <pose degrees="true">0 0 0 180 0 0</pose>
                <always_on>1</always_on>
                <update_rate>1000.0</update_rate>
            </sensor>
        </link>
        <joint name='imu_joint' type='revolute'>
            <child>imu_link</child>
            <parent>base_link</parent>
            <axis>
                <xyz>0 0 1</xyz>
                <limit>
                <lower>0</lower>
                <upper>0</upper>
                <effort>0</effort>
                <velocity>0</velocity>
                </limit>
                <dynamics>
                <damping>1.0</damping>
                </dynamics>
            </axis>
        </joint>

        <!-- PLUGINS -->
        <plugin filename="gz-sim-joint-state-publisher-system"
        name="gz::sim::systems::JointStatePublisher">
        </plugin>
        <plugin filename="gz-sim-lift-drag-system"
            name="gz::sim::systems::LiftDrag">
        <a0>0.3</a0>
        <alpha_stall>1.4</alpha_stall>
        <cla>4.2500</cla>
        <cda>0.10</cda>
        <cma>0.0</cma>
        <cla_stall>-0.025</cla_stall>
        <cda_stall>0.0</cda_stall>
        <cma_stall>0.0</cma_stall>
        <area>0.002</area>
        <air_density>1.2041</air_density>
        <cp>0.127 0 0</cp>
        <forward>0 1 0</forward>
        <upward>0 0 1</upward>
        <link_name>Prop1</link_name>
        </plugin>
        <plugin filename="gz-sim-lift-drag-system"
            name="gz::sim::systems::LiftDrag">
        <a0>0.3</a0>
        <alpha_stall>1.4</alpha_stall>
        <cla>4.2500</cla>
        <cda>0.10</cda>
        <cma>0.0</cma>
        <cla_stall>-0.025</cla_stall>
        <cda_stall>0.0</cda_stall>
        <cma_stall>0.0</cma_stall>
        <area>0.002</area>
        <air_density>1.2041</air_density>
        <cp>-0.127 0 0</cp>
        <forward>0 -1 0</forward>
        <upward>0 0 1</upward>
        <link_name>Prop1</link_name>
        </plugin>

        <plugin filename="gz-sim-lift-drag-system"
            name="gz::sim::systems::LiftDrag">
        <a0>0.3</a0>
        <alpha_stall>1.4</alpha_stall>
        <cla>4.2500</cla>
        <cda>0.10</cda>
        <cma>0.0</cma>
        <cla_stall>-0.025</cla_stall>
        <cda_stall>0.0</cda_stall>
        <cma_stall>0.0</cma_stall>
        <area>0.002</area>
        <air_density>1.2041</air_density>
        <cp>0.127 0 0</cp>
        <forward>0 1 0</forward>
        <upward>0 0 1</upward>
        <link_name>Prop2</link_name>
        </plugin>
        <plugin filename="gz-sim-lift-drag-system"
            name="gz::sim::systems::LiftDrag">
        <a0>0.3</a0>
        <alpha_stall>1.4</alpha_stall>
        <cla>4.2500</cla>
        <cda>0.10</cda>
        <cma>0.0</cma>
        <cla_stall>-0.025</cla_stall>
        <cda_stall>0.0</cda_stall>
        <cma_stall>0.0</cma_stall>
        <area>0.002</area>
        <air_density>1.2041</air_density>
        <cp>-0.127 0 0</cp>
        <forward>0 -1 0</forward>
        <upward>0 0 1</upward>
        <link_name>Prop2</link_name>
        </plugin>

        <plugin filename="gz-sim-lift-drag-system"
            name="gz::sim::systems::LiftDrag">
        <a0>0.3</a0>
        <alpha_stall>1.4</alpha_stall>
        <cla>4.2500</cla>
        <cda>0.10</cda>
        <cma>0.0</cma>
        <cla_stall>-0.025</cla_stall>
        <cda_stall>0.0</cda_stall>
        <cma_stall>0.0</cma_stall>
        <area>0.002</area>
        <air_density>1.2041</air_density>
        <cp>0.127 0 0</cp>
        <forward>0 -1 0</forward>
        <upward>0 0 1</upward>
        <link_name>Prop3</link_name>
        </plugin>
        <plugin filename="gz-sim-lift-drag-system"
            name="gz::sim::systems::LiftDrag">
        <a0>0.3</a0>
        <alpha_stall>1.4</alpha_stall>
        <cla>4.2500</cla>
        <cda>0.10</cda>
        <cma>0.0</cma>
        <cla_stall>-0.025</cla_stall>
        <cda_stall>0.0</cda_stall>
        <cma_stall>0.0</cma_stall>
        <area>0.002</area>
        <air_density>1.2041</air_density>
        <cp>-0.127 0 0</cp>
        <forward>0 1 0</forward>
        <upward>0 0 1</upward>
        <link_name>Prop3</link_name>
        </plugin>

        <plugin filename="gz-sim-lift-drag-system"
            name="gz::sim::systems::LiftDrag">
        <a0>0.3</a0>
        <alpha_stall>1.4</alpha_stall>
        <cla>4.2500</cla>
        <cda>0.10</cda>
        <cma>0.0</cma>
        <cla_stall>-0.025</cla_stall>
        <cda_stall>0.0</cda_stall>
        <cma_stall>0.0</cma_stall>
        <area>0.002</area>
        <air_density>1.2041</air_density>
        <cp>0.127 0 0</cp>
        <forward>0 -1 0</forward>
        <upward>0 0 1</upward>
        <link_name>Prop4</link_name>
        </plugin>
        <plugin filename="gz-sim-lift-drag-system"
            name="gz::sim::systems::LiftDrag">
        <a0>0.3</a0>
        <alpha_stall>1.4</alpha_stall>
        <cla>4.2500</cla>
        <cda>0.10</cda>
        <cma>0.0</cma>
        <cla_stall>-0.025</cla_stall>
        <cda_stall>0.0</cda_stall>
        <cma_stall>0.0</cma_stall>
        <area>0.002</area>
        <air_density>1.2041</air_density>
        <cp>-0.127 0 0</cp>
        <forward>0 1 0</forward>
        <upward>0 0 1</upward>
        <link_name>Prop4</link_name>
        </plugin>

        <plugin filename="gz-sim-apply-joint-force-system"
        name="gz::sim::systems::ApplyJointForce">
        <joint_name>Prop1-joint</joint_name>
        </plugin>
        <plugin filename="gz-sim-apply-joint-force-system"
        name="gz::sim::systems::ApplyJointForce">
        <joint_name>Prop2-joint</joint_name>
        </plugin>
        <plugin filename="gz-sim-apply-joint-force-system"
        name="gz::sim::systems::ApplyJointForce">
        <joint_name>Prop3-joint</joint_name>
        </plugin>
        <plugin filename="gz-sim-apply-joint-force-system"
        name="gz::sim::systems::ApplyJointForce">
        <joint_name>Prop4-joint</joint_name>
        </plugin>

        <plugin name="ArduPilotPlugin"
        filename="ArduPilotPlugin">
        <!-- Port settings -->
        <fdm_addr>127.0.0.1</fdm_addr>
        <fdm_port_in>9002</fdm_port_in>
        <connectionTimeoutMaxCount>5</connectionTimeoutMaxCount>
        <lock_step>1</lock_step>
        <have_32_channels>0</have_32_channels>

        <!-- Frame conventions
            Require by ArduPilot: change model and gazebo from XYZ to XY-Z coordinates
        -->
        <modelXYZToAirplaneXForwardZDown degrees="true">0 0 0 180 0 0</modelXYZToAirplaneXForwardZDown>
        <gazeboXYZToNED degrees="true">0 0 0 180 0 90</gazeboXYZToNED>

        <!-- Sensors -->
        <imuName>imu_sensor</imuName>

        <!--
            incoming control command [0, 1]
            so offset it by 0 to get [0, 1]
            and divide max target by 1.
            offset = 0
            multiplier = 838 max rpm / 1 = 838
            -->
        <control channel="0">
            <jointName>Prop1-joint</jointName>
            <useForce>1</useForce>
            <multiplier>838</multiplier>
            <offset>0</offset>
            <servo_min>1100</servo_min>
            <servo_max>1900</servo_max>
            <type>VELOCITY</type>
            <p_gain>0.20</p_gain>
            <i_gain>0.0</i_gain>
            <d_gain>0.0</d_gain>
            <i_max>0</i_max>
            <i_min>0</i_min>
            <cmd_max>3.50</cmd_max>
            <cmd_min>-3.50</cmd_min>
            <controlVelocitySlowdownSim>1</controlVelocitySlowdownSim>
        </control>

        <control channel="1">
            <jointName>Prop2-joint</jointName>
            <useForce>1</useForce>
            <multiplier>838</multiplier>
            <offset>0</offset>
            <servo_min>1100</servo_min>
            <servo_max>1900</servo_max>
            <type>VELOCITY</type>
            <p_gain>0.20</p_gain>
            <i_gain>0.0</i_gain>
            <d_gain>0.0</d_gain>
            <i_max>0</i_max>
            <i_min>0</i_min>
            <cmd_max>3.50</cmd_max>
            <cmd_min>-3.50</cmd_min>
            <controlVelocitySlowdownSim>1</controlVelocitySlowdownSim>
        </control>

        <control channel="2">
            <jointName>Prop3-joint</jointName>
            <useForce>1</useForce>
            <multiplier>-838</multiplier>
            <offset>0</offset>
            <servo_min>1100</servo_min>
            <servo_max>1900</servo_max>
            <type>VELOCITY</type>
            <p_gain>0.20</p_gain>
            <i_gain>0.0</i_gain>
            <d_gain>0.0</d_gain>
            <i_max>0</i_max>
            <i_min>0</i_min>
            <cmd_max>3.50</cmd_max>
            <cmd_min>-3.50</cmd_min>
            <controlVelocitySlowdownSim>1</controlVelocitySlowdownSim>
        </control>

        <control channel="3">
            <jointName>Prop4-joint</jointName>
            <useForce>1</useForce>
            <multiplier>-838</multiplier>
            <offset>0</offset>
            <servo_min>1100</servo_min>
            <servo_max>1900</servo_max>
            <type>VELOCITY</type>
            <p_gain>0.20</p_gain>
            <i_gain>0.00</i_gain>
            <d_gain>0.0</d_gain>
            <i_max>0</i_max>
            <i_min>0</i_min>
            <cmd_max>3.50</cmd_max>
            <cmd_min>-3.50</cmd_min>
            <controlVelocitySlowdownSim>1</controlVelocitySlowdownSim>
        </control>

        </plugin>
    </model>
</sdf>